Workbook

Sheet Financials>

Sheet HistoricalFS
B2: ="Historical Financial Statements - "&'Data Sheet'!B1 -> Historical Financial Statements - FSN E-COMMERCE VENTURES LTD
B3: Years | C3: ='Data Sheet'!C16 -> 43190 | D3: ='Data Sheet'!D16 -> 43555 | E3: ='Data Sheet'!E16 -> 43921 | F3: ='Data Sheet'!F16 -> 44286 | G3: ='Data Sheet'!G16 -> 44651 | H3: ='Data Sheet'!H16 -> 45016 | I3: ='Data Sheet'!I16 -> 45382 | J3: ='Data Sheet'!J16 -> 45747 | K3: ='Data Sheet'!K16 -> 46112 | L3: LTM
B5: #Income Statements
B6: Sales | C6: =IFERROR('Data Sheet'!C17,0) -> 574.36 | D6: =IFERROR('Data Sheet'!D17,0) -> 1111.39 | E6: =IFERROR('Data Sheet'!E17,0) -> 1767.53 | F6: =IFERROR('Data Sheet'!F17,0) -> 2440.9 | G6: =IFERROR('Data Sheet'!G17,0) -> 3773.94 | H6: =IFERROR('Data Sheet'!H17,0) -> 5143.8 | I6: =IFERROR('Data Sheet'!I17,0) -> 6385.63 | J6: =IFERROR('Data Sheet'!J17,0) -> 7949.82 | K6: =IFERROR('Data Sheet'!K17,0) -> 10022.35 | L6: =IFERROR(SUM('Data Sheet'!H42:K42),0) -> 10022.35
B7: Sales Growth | C7: - | D7: =D6/C6-1 -> 0.93500592 | E7: =E6/D6-1 -> 0.59037782 | F7: =F6/E6-1 -> 0.38096666 | G7: =G6/F6-1 -> 0.54612643 | H7: =H6/G6-1 -> 0.36297874 | I7: =I6/H6-1 -> 0.24142268 | J7: =J6/I6-1 -> 0.24495469 | K7: =K6/J6-1 -> 0.2607015 | L7: =L6/K6-1 -> 0
B9: COGS | C9: =IFERROR(SUM('Data Sheet'!C18,'Data Sheet'!C20:C22),0)-1*'Data Sheet'!C19 -> 459.05 | D9: =IFERROR(SUM('Data Sheet'!D18,'Data Sheet'!D20:D22),0)-1*'Data Sheet'!D19 -> 827.75 | E9: =IFERROR(SUM('Data Sheet'!E18,'Data Sheet'!E20:E22),0)-1*'Data Sheet'!E19 -> 1285.21 | F9: =IFERROR(SUM('Data Sheet'!F18,'Data Sheet'!F20:F22),0)-1*'Data Sheet'!F19 -> 1867.38 | G9: =IFERROR(SUM('Data Sheet'!G18,'Data Sheet'!G20:G22),0)-1*'Data Sheet'!G19 -> 2697.5 | H9: =IFERROR(SUM('Data Sheet'!H18,'Data Sheet'!H20:H22),0)-1*'Data Sheet'!H19 -> 3573.2 | I9: =IFERROR(SUM('Data Sheet'!I18,'Data Sheet'!I20:I22),0)-1*'Data Sheet'!I19 -> 4422.08 | J9: =IFERROR(SUM('Data Sheet'!J18,'Data Sheet'!J20:J22),0)-1*'Data Sheet'!J19 -> 5382.29 | K9: =IFERROR(SUM('Data Sheet'!K18,'Data Sheet'!K20:K22),0)-1*'Data Sheet'!K19 -> 6278.06 | L9: =IFERROR(SUM('Data Sheet'!H43:K43),0) -> 9270.04
B10: COGS % Sales | C10: =C9/C6 -> 0.79923741 | D10: =D9/D6 -> 0.74478806 | E10: =E9/E6 -> 0.72712203 | F10: =F9/F6 -> 0.76503749 | G10: =G9/G6 -> 0.71477024 | H10: =H9/H6 -> 0.69466153 | I10: =I9/I6 -> 0.69250489 | J10: =J9/J6 -> 0.67703294 | ... L10: =L9/L6 -> 0.92493677
B12: Gross Profit | C12: =C6-C9 -> 115.31 | D12: =D6-D9 -> 283.64 | E12: =E6-E9 -> 482.32 | F12: =F6-F9 -> 573.52 | G12: =G6-G9 -> 1076.44 | H12: =H6-H9 -> 1570.6 | I12: =I6-I9 -> 1963.55 | J12: =J6-J9 -> 2567.53 | ... L12: =L6-L9 -> 752.31
B13: Gross Margins % Sales | C13: =C12/C6 -> 0.20076259 | D13: =D12/D6 -> 0.25521194 | E13: =E12/E6 -> 0.27287797 | F13: =F12/F6 -> 0.23496251 | G13: =G12/G6 -> 0.28522976 | H13: =H12/H6 -> 0.30533847 | I13: =I12/I6 -> 0.30749511 | J13: =J12/J6 -> 0.32296706 | ... L13: =L12/L6 -> 0.075063234
B15: Selling & General Expenses | C15: =IFERROR(SUM('Data Sheet'!C23:C24),0) -> 141.92 | D15: =IFERROR(SUM('Data Sheet'!D23:D24),0) -> 262.78 | E15: =IFERROR(SUM('Data Sheet'!E23:E24),0) -> 399.32 | F15: =IFERROR(SUM('Data Sheet'!F23:F24),0) -> 415.28 | G15: =IFERROR(SUM('Data Sheet'!G23:G24),0) -> 912.39 | H15: =IFERROR(SUM('Data Sheet'!H23:H24),0) -> 1313.54 | I15: =IFERROR(SUM('Data Sheet'!I23:I24),0) -> 1616.67 | J15: =IFERROR(SUM('Data Sheet'!J23:J24),0) -> 2092.75 | ... L15: =IFERROR(SUM('Data Sheet'!L23:L24),0) -> 0
B16: S&G Expenses % Sales | C16: =C15/C6 -> 0.24709242 | D16: =D15/D6 -> 0.23644265 | E16: =E15/E6 -> 0.22591979 | F16: =F15/F6 -> 0.17013397 | G16: =G15/G6 -> 0.2417606 | H16: =H15/H6 -> 0.25536374 | I16: =I15/I6 -> 0.25317314 | J16: =J15/J6 -> 0.26324495 | ... L16: =L15/L6 -> 0
B18: EBITDA | C18: =C12-C15 -> -26.61 | D18: =D12-D15 -> 20.86 | E18: =E12-E15 -> 83 | F18: =F12-F15 -> 158.24 | G18: =G12-G15 -> 164.05 | H18: =H12-H15 -> 257.06 | I18: =I12-I15 -> 346.88 | J18: =J12-J15 -> 474.78 | ... L18: =L12-L15 -> 752.31
B19: EBITDA % Sales | C19: =C18/C6 -> -0.046329828 | D19: =D18/D6 -> 0.018769289 | E19: =E18/E6 -> 0.046958185 | F19: =F18/F6 -> 0.064828547 | G19: =G18/G6 -> 0.04346916 | H19: =H18/H6 -> 0.049974727 | I19: =I18/I6 -> 0.05432197 | J19: =J18/J6 -> 0.059722107 | ... L19: =L18/L6 -> 0.075063234
B21: Interest | C21: =IFERROR('Data Sheet'!C27,0) -> 7.16 | D21: =IFERROR('Data Sheet'!D27,0) -> 26.69 | E21: =IFERROR('Data Sheet'!E27,0) -> 46.24 | F21: =IFERROR('Data Sheet'!F27,0) -> 32.29 | G21: =IFERROR('Data Sheet'!G27,0) -> 47.3 | H21: =IFERROR('Data Sheet'!H27,0) -> 75.62 | I21: =IFERROR('Data Sheet'!I27,0) -> 83.56 | J21: =IFERROR('Data Sheet'!J27,0) -> 108.19 | K21: =IFERROR('Data Sheet'!K27,0) -> 117.12 | L21: =IFERROR(SUM('Data Sheet'!H46:K46),0) -> 117.12
B22: Interest % of Sales | C22: =C21/C6 -> 0.012466049 | D22: =D21/D6 -> 0.024014972 | E22: =E21/E6 -> 0.026160801 | F22: =F21/F6 -> 0.013228727 | G22: =G21/G6 -> 0.012533321 | H22: =H21/H6 -> 0.014701194 | I22: =I21/I6 -> 0.013085631 | J22: =J21/J6 -> 0.013609113 | ... L22: =L21/L6 -> 0.011685882
B24: Depreciation | C24: =IFERROR('Data Sheet'!C26,0) -> 7.4 | D24: =IFERROR('Data Sheet'!D26,0) -> 30.88 | E24: =IFERROR('Data Sheet'!E26,0) -> 59.51 | F24: =IFERROR('Data Sheet'!F26,0) -> 71.59 | G24: =IFERROR('Data Sheet'!G26,0) -> 96.41 | H24: =IFERROR('Data Sheet'!H26,0) -> 173.26 | I24: =IFERROR('Data Sheet'!I26,0) -> 224.23 | J24: =IFERROR('Data Sheet'!J26,0) -> 266.4 | K24: =IFERROR('Data Sheet'!K26,0) -> 320.33 | L24: =IFERROR(SUM('Data Sheet'!H45:K45),0) -> 320.33
B25: Depreciation % Sales | C25: =C24/C6 -> 0.012883906 | D25: =D24/D6 -> 0.027785026 | E25: =E24/E6 -> 0.033668453 | F25: =F24/F6 -> 0.029329346 | G25: =G24/G6 -> 0.025546246 | H25: =H24/H6 -> 0.033683269 | I25: =I24/I6 -> 0.035114781 | J25: =J24/J6 -> 0.033510193 | ... L25: =L24/L6 -> 0.031961566
B27: EBT | C27: =IFERROR(C18-SUM(C21,C24),0) -> -41.17 | D27: =IFERROR(D18-SUM(D21,D24),0) -> -36.71 | E27: =IFERROR(E18-SUM(E21,E24),0) -> -22.75 | F27: =IFERROR(F18-SUM(F21,F24),0) -> 54.36 | G27: =IFERROR(G18-SUM(G21,G24),0) -> 20.34 | H27: =IFERROR(H18-SUM(H21,H24),0) -> 8.18 | I27: =IFERROR(I18-SUM(I21,I24),0) -> 39.09 | J27: =IFERROR(J18-SUM(J21,J24),0) -> 100.19 | ... L27: =IFERROR(L18-SUM(L21,L24),0) -> 314.86
B28: EBT % Sales | C28: =C27/C6 -> -0.071679783 | D28: =D27/D6 -> -0.033030709 | E28: =E27/E6 -> -0.012871069 | F28: =F27/F6 -> 0.022270474 | G28: =G27/G6 -> 0.0053895928 | H28: =H27/H6 -> 0.001590264 | I28: =I27/I6 -> 0.0061215573 | J28: =J27/J6 -> 0.012602801 | ... L28: =L27/L6 -> 0.031415786
B30: Tax | C30: =IFERROR('Data Sheet'!C29,0) -> -9.27 | D30: =IFERROR('Data Sheet'!D29,0) -> -7.18 | E30: =IFERROR('Data Sheet'!E29,0) -> 3.91 | F30: =IFERROR('Data Sheet'!F29,0) -> 4.48 | G30: =IFERROR('Data Sheet'!G29,0) -> 6.02 | H30: =IFERROR('Data Sheet'!H29,0) -> 13.57 | I30: =IFERROR('Data Sheet'!I29,0) -> 25.32 | J30: =IFERROR('Data Sheet'!J29,0) -> 53.75 | K30: =IFERROR('Data Sheet'!K29,0) -> 126.29 | L30: =IFERROR(SUM('Data Sheet'!H48:K48),0) -> 126.29
B31: Effective Tax Rate | C31: =C30/C27 -> 0.22516395 | D31: =D30/D27 -> 0.19558703 | E31: =E30/E27 -> -0.17186813 | F31: =F30/F27 -> 0.082413539 | G31: =G30/G27 -> 0.29596853 | H31: =H30/H27 -> 1.6589242 | I31: =I30/I27 -> 0.64773599 | J31: =J30/J27 -> 0.53648069 | ... L31: =L30/L27 -> 0.4010989
B33: Net Profit | C33: =IFERROR(C27-C30,0) -> -31.9 | D33: =IFERROR(D27-D30,0) -> -29.53 | E33: =IFERROR(E27-E30,0) -> -26.66 | F33: =IFERROR(F27-F30,0) -> 49.88 | G33: =IFERROR(G27-G30,0) -> 14.32 | H33: =IFERROR(H27-H30,0) -> -5.39 | I33: =IFERROR(I27-I30,0) -> 13.77 | J33: =IFERROR(J27-J30,0) -> 46.44 | ... L33: =IFERROR(L27-L30,0) -> 188.57
B34: Net Margins | C34: =C33/C6 -> -0.055540079 | D34: =D33/D6 -> -0.026570331 | E34: =E33/E6 -> -0.015083195 | F34: =F33/F6 -> 0.020435085 | G34: =G33/G6 -> 0.0037944429 | H34: =H33/H6 -> -0.0010478634 | I34: =I33/I6 -> 0.0021564043 | J34: =J33/J6 -> 0.0058416417 | ... L34: =L33/L6 -> 0.018814949
B36: No. Of Equity Shares | C36: =IFERROR('Data Sheet'!C93,0) -> 8.13 | D36: =IFERROR('Data Sheet'!D93,0) -> 8.55 | E36: =IFERROR('Data Sheet'!E93,0) -> 8.73 | F36: =IFERROR('Data Sheet'!F93,0) -> 9.03 | G36: =IFERROR('Data Sheet'!G93,0) -> 284.46 | H36: =IFERROR('Data Sheet'!H93,0) -> 285.24 | I36: =IFERROR('Data Sheet'!I93,0) -> 285.6 | J36: =IFERROR('Data Sheet'!J93,0) -> 285.93 | K36: =IFERROR('Data Sheet'!K93,0) -> 286.32 | L36: =K36 -> 286.32
B38: Earnings Per Share | C38: =IFERROR(C33/C36,0) -> -3.9237392 | D38: =IFERROR(D33/D36,0) -> -3.4538012 | E38: =IFERROR(E33/E36,0) -> -3.0538373 | F38: =IFERROR(F33/F36,0) -> 5.5238095 | G38: =IFERROR(G33/G36,0) -> 0.050340997 | H38: =IFERROR(H33/H36,0) -> -0.018896368 | I38: =IFERROR(I33/I36,0) -> 0.048214286 | J38: =IFERROR(J33/J36,0) -> 0.16241737 | ... L38: =IFERROR(L33/L36,0) -> 0.65859877
B39: EPS Growth % | C39: - | D39: =IFERROR((D38-C38)/ABS(C38),0) -> 0.11976792 | E39: =IFERROR((E38-D38)/ABS(D38),0) -> 0.11580395 | F39: =IFERROR((F38-E38)/ABS(E38),0) -> 2.8088093 | G39: =IFERROR((G38-F38)/ABS(F38),0) -> -0.99088654 | H39: =IFERROR((H38-G38)/ABS(G38),0) -> -1.3753674 | I39: =IFERROR((I38-H38)/ABS(H38),0) -> 3.5515107 | J39: =IFERROR((J38-I38)/ABS(I38),0) -> 2.3686567 | K39: =IFERROR((K38-J38)/ABS(J38),0) -> 3.0549773 | L39: =IFERROR((L38-K38)/ABS(K38),0) -> -7.4172342e-15
B41: Dividend | C41: =IFERROR('Data Sheet'!C31/C36,0) -> 0 | D41: =IFERROR('Data Sheet'!D31/D36,0) -> 0 | E41: =IFERROR('Data Sheet'!E31/E36,0) -> 0 | F41: =IFERROR('Data Sheet'!F31/F36,0) -> 0 | G41: =IFERROR('Data Sheet'!G31/G36,0) -> 0 | H41: =IFERROR('Data Sheet'!H31/H36,0) -> 0 | I41: =IFERROR('Data Sheet'!I31/I36,0) -> 0 | J41: =IFERROR('Data Sheet'!J31/J36,0) -> 0 | ... L41: =IFERROR('Data Sheet'!L31/L36,0) -> 0
B42: Dividend Payout Ratio | C42: =IFERROR(C41/C38,0) -> 0 | D42: =IFERROR(D41/D38,0) -> 0 | E42: =IFERROR(E41/E38,0) -> 0 | F42: =IFERROR(F41/F38,0) -> 0 | G42: =IFERROR(G41/G38,0) -> 0 | H42: =IFERROR(H41/H38,0) -> 0 | I42: =IFERROR(I41/I38,0) -> 0 | J42: =IFERROR(J41/J38,0) -> 0 | ... L42: =IFERROR(L41/L38,0) -> 0
B44: Retained Earnings | C44: =IFERROR(IF(C38>C41,1-C42,0),0) -> 0 | D44: =IFERROR(IF(D38>D41,1-D42,0),0) -> 0 | E44: =IFERROR(IF(E38>E41,1-E42,0),0) -> 0 | F44: =IFERROR(IF(F38>F41,1-F42,0),0) -> 1 | G44: =IFERROR(IF(G38>G41,1-G42,0),0) -> 1 | H44: =IFERROR(IF(H38>H41,1-H42,0),0) -> 0 | I44: =IFERROR(IF(I38>I41,1-I42,0),0) -> 1 | J44: =IFERROR(IF(J38>J41,1-J42,0),0) -> 1 | ... L44: =IFERROR(IF(L38>L41,1-L42,0),0) -> 1
B46: #Balance Sheet
B47: Equity Share Capital | C47: =IFERROR('Data Sheet'!C57,0) -> 13.56 | D47: =IFERROR('Data Sheet'!D57,0) -> 14.24 | E47: =IFERROR('Data Sheet'!E57,0) -> 14.55 | F47: =IFERROR('Data Sheet'!F57,0) -> 15.06 | G47: =IFERROR('Data Sheet'!G57,0) -> 47.41 | H47: =IFERROR('Data Sheet'!H57,0) -> 285.25 | I47: =IFERROR('Data Sheet'!I57,0) -> 285.6 | J47: =IFERROR('Data Sheet'!J57,0) -> 285.93 | K47: =IFERROR('Data Sheet'!K57,0) -> 286.33
B48: Reserves | C48: =IFERROR('Data Sheet'!C58,0) -> 108.03 | D48: =IFERROR('Data Sheet'!D58,0) -> 216.32 | E48: =IFERROR('Data Sheet'!E58,0) -> 307.4 | F48: =IFERROR('Data Sheet'!F58,0) -> 474.51 | G48: =IFERROR('Data Sheet'!G58,0) -> 1292.49 | H48: =IFERROR('Data Sheet'!H58,0) -> 1092.77 | I48: =IFERROR('Data Sheet'!I58,0) -> 976.63 | J48: =IFERROR('Data Sheet'!J58,0) -> 1015.35 | K48: =IFERROR('Data Sheet'!K58,0) -> 1151.65
B49: Borrowings | C49: =IFERROR('Data Sheet'!C59,0) -> 83.05 | D49: =IFERROR('Data Sheet'!D59,0) -> 310.47 | E49: =IFERROR('Data Sheet'!E59,0) -> 412.77 | F49: =IFERROR('Data Sheet'!F59,0) -> 333 | G49: =IFERROR('Data Sheet'!G59,0) -> 592.62 | H49: =IFERROR('Data Sheet'!H59,0) -> 798.5 | I49: =IFERROR('Data Sheet'!I59,0) -> 969.49 | J49: =IFERROR('Data Sheet'!J59,0) -> 1320.59 | K49: =IFERROR('Data Sheet'!K59,0) -> 1237.81
B50: Other Liabilities | C50: =IFERROR('Data Sheet'!C60,0) -> 148.5 | D50: =IFERROR('Data Sheet'!D60,0) -> 234.62 | E50: =IFERROR('Data Sheet'!E60,0) -> 389.76 | F50: =IFERROR('Data Sheet'!F60,0) -> 479.37 | G50: =IFERROR('Data Sheet'!G60,0) -> 713.52 | H50: =IFERROR('Data Sheet'!H60,0) -> 773.45 | I50: =IFERROR('Data Sheet'!I60,0) -> 1168.91 | J50: =IFERROR('Data Sheet'!J60,0) -> 1357.66 | K50: =IFERROR('Data Sheet'!K60,0) -> 1935.59
B51: Total Liabilities | C51: =IFERROR('Data Sheet'!C61,0) -> 353.14 | D51: =IFERROR('Data Sheet'!D61,0) -> 775.65 | E51: =IFERROR('Data Sheet'!E61,0) -> 1124.48 | F51: =IFERROR('Data Sheet'!F61,0) -> 1301.94 | G51: =IFERROR('Data Sheet'!G61,0) -> 2646.04 | H51: =IFERROR('Data Sheet'!H61,0) -> 2949.97 | I51: =IFERROR('Data Sheet'!I61,0) -> 3400.63 | J51: =IFERROR('Data Sheet'!J61,0) -> 3979.53 | K51: =IFERROR('Data Sheet'!K61,0) -> 4611.38
B53: Fixed Assets Net Block | C53: =IFERROR('Data Sheet'!C62,0) -> 34.12 | D53: =IFERROR('Data Sheet'!D62,0) -> 139.58 | E53: =IFERROR('Data Sheet'!E62,0) -> 227.03 | F53: =IFERROR('Data Sheet'!F62,0) -> 231.13 | G53: =IFERROR('Data Sheet'!G62,0) -> 483.25 | H53: =IFERROR('Data Sheet'!H62,0) -> 698.82 | I53: =IFERROR('Data Sheet'!I62,0) -> 668.16 | J53: =IFERROR('Data Sheet'!J62,0) -> 834.82 | K53: =IFERROR('Data Sheet'!K62,0) -> 1007.95
B54: Capital Work in Progress | C54: =IFERROR('Data Sheet'!C63,0) -> 0.44 | D54: =IFERROR('Data Sheet'!D63,0) -> 0.32 | E54: =IFERROR('Data Sheet'!E63,0) -> 2.02 | F54: =IFERROR('Data Sheet'!F63,0) -> 2.36 | G54: =IFERROR('Data Sheet'!G63,0) -> 24.5 | H54: =IFERROR('Data Sheet'!H63,0) -> 30.88 | I54: =IFERROR('Data Sheet'!I63,0) -> 29.78 | J54: =IFERROR('Data Sheet'!J63,0) -> 36.74 | K54: =IFERROR('Data Sheet'!K63,0) -> 9.25
B55: Investments | C55: =IFERROR('Data Sheet'!C64,0) -> 10.42 | D55: =IFERROR('Data Sheet'!D64,0) -> 138.27 | E55: =IFERROR('Data Sheet'!E64,0) -> 3.8 | F55: =IFERROR('Data Sheet'!F64,0) -> 1.32 | G55: =IFERROR('Data Sheet'!G64,0) -> 0 | H55: =IFERROR('Data Sheet'!H64,0) -> 38.12 | I55: =IFERROR('Data Sheet'!I64,0) -> 34.31 | J55: =IFERROR('Data Sheet'!J64,0) -> 0.16 | K55: =IFERROR('Data Sheet'!K64,0) -> 0.16
B56: Other Assets | C56: =IFERROR('Data Sheet'!C65-SUM('Data Sheet'!C67:C69),0) -> 82.51 | D56: =IFERROR('Data Sheet'!D65-SUM('Data Sheet'!D67:D69),0) -> 183.02 | E56: =IFERROR('Data Sheet'!E65-SUM('Data Sheet'!E67:E69),0) -> 172.24 | F56: =IFERROR('Data Sheet'!F65-SUM('Data Sheet'!F67:F69),0) -> 244.73 | G56: =IFERROR('Data Sheet'!G65-SUM('Data Sheet'!G67:G69),0) -> 901.1 | H56: =IFERROR('Data Sheet'!H65-SUM('Data Sheet'!H67:H69),0) -> 864.74 | I56: =IFERROR('Data Sheet'!I65-SUM('Data Sheet'!I67:I69),0) -> 994.87 | J56: =IFERROR('Data Sheet'!J65-SUM('Data Sheet'!J67:J69),0) -> 1226.51 | K56: =IFERROR('Data Sheet'!K65-SUM('Data Sheet'!K67:K69),0) -> 1342.45
B57: Total Non Current Assets | C57: =IFERROR(SUM(C53:C56),0) -> 127.49 | D57: =IFERROR(SUM(D53:D56),0) -> 461.19 | E57: =IFERROR(SUM(E53:E56),0) -> 405.09 | F57: =IFERROR(SUM(F53:F56),0) -> 479.54 | G57: =IFERROR(SUM(G53:G56),0) -> 1408.85 | H57: =IFERROR(SUM(H53:H56),0) -> 1632.56 | I57: =IFERROR(SUM(I53:I56),0) -> 1727.12 | J57: =IFERROR(SUM(J53:J56),0) -> 2098.23 | K57: =IFERROR(SUM(K53:K56),0) -> 2359.81
...

Sheet Ratio Analysis
B2: ="Ratio Analysis - "&'Data Sheet'!B1 -> Ratio Analysis - FSN E-COMMERCE VENTURES LTD
B3: Years | C3: ='Data Sheet'!C16 -> 43190 | D3: ='Data Sheet'!D16 -> 43555 | E3: ='Data Sheet'!E16 -> 43921 | F3: ='Data Sheet'!F16 -> 44286 | G3: ='Data Sheet'!G16 -> 44651 | H3: ='Data Sheet'!H16 -> 45016 | I3: ='Data Sheet'!I16 -> 45382 | J3: ='Data Sheet'!J16 -> 45747 | K3: ='Data Sheet'!K16 -> 46112 | L3: Trend | M3: Mean | N3: Median
B5: Sales Growth | D5: =IFERROR(HistoricalFS!D16,0) -> 0.23644265 | E5: =IFERROR(HistoricalFS!E16,0) -> 0.22591979 | F5: =IFERROR(HistoricalFS!F16,0) -> 0.17013397 | G5: =IFERROR(HistoricalFS!G16,0) -> 0.2417606 | H5: =IFERROR(HistoricalFS!H16,0) -> 0.25536374 | I5: =IFERROR(HistoricalFS!I16,0) -> 0.25317314 | J5: =IFERROR(HistoricalFS!J16,0) -> 0.26324495 | K5: =IFERROR(HistoricalFS!K16,0) -> 0.29853078 | M5: =IFERROR(AVERAGE(D5:K5),0) -> 0.2430712 | N5: =IFERROR(MEDIAN(D5:K5),0) -> 0.24746687
B6: EBITDA Growth | D6: =IFERROR(HistoricalFS!D18/HistoricalFS!C18-1,0) -> -1.7839158 | E6: =IFERROR(HistoricalFS!E18/HistoricalFS!D18-1,0) -> 2.978907 | F6: =IFERROR(HistoricalFS!F18/HistoricalFS!E18-1,0) -> 0.90650602 | G6: =IFERROR(HistoricalFS!G18/HistoricalFS!F18-1,0) -> 0.03671638 | H6: =IFERROR(HistoricalFS!H18/HistoricalFS!G18-1,0) -> 0.56696129 | I6: =IFERROR(HistoricalFS!I18/HistoricalFS!H18-1,0) -> 0.34941259 | J6: =IFERROR(HistoricalFS!J18/HistoricalFS!I18-1,0) -> 0.36871541 | K6: =IFERROR(HistoricalFS!K18/HistoricalFS!J18-1,0) -> 0.58454442 | M6: =IFERROR(AVERAGE(D6:K6),0) -> 0.50098091 | N6: =IFERROR(MEDIAN(D6:K6),0) -> 0.46783835
B7: EBT Growth | D7: =IFERROR(HistoricalFS!D27/HistoricalFS!C27-1,0) -> -0.10833131 | E7: =IFERROR(HistoricalFS!E27/HistoricalFS!D27-1,0) -> -0.38027785 | F7: =IFERROR(HistoricalFS!F27/HistoricalFS!E27-1,0) -> -3.3894505 | G7: =IFERROR(HistoricalFS!G27/HistoricalFS!F27-1,0) -> -0.62582781 | H7: =IFERROR(HistoricalFS!H27/HistoricalFS!G27-1,0) -> -0.59783677 | I7: =IFERROR(HistoricalFS!I27/HistoricalFS!H27-1,0) -> 3.7787286 | J7: =IFERROR(HistoricalFS!J27/HistoricalFS!I27-1,0) -> 1.5630596 | K7: =IFERROR(HistoricalFS!K27/HistoricalFS!J27-1,0) -> 2.142629 | M7: =IFERROR(AVERAGE(D7:K7),0) -> 0.29783661 | N7: =IFERROR(MEDIAN(D7:K7),0) -> -0.24430458
B8: Net Profit Growth | D8: =IFERROR(HistoricalFS!D33/HistoricalFS!C33-1,0) -> -0.074294671 | E8: =IFERROR(HistoricalFS!E33/HistoricalFS!D33-1,0) -> -0.097189299 | F8: =IFERROR(HistoricalFS!F33/HistoricalFS!E33-1,0) -> -2.8709677 | G8: =IFERROR(HistoricalFS!G33/HistoricalFS!F33-1,0) -> -0.71291099 | H8: =IFERROR(HistoricalFS!H33/HistoricalFS!G33-1,0) -> -1.3763966 | I8: =IFERROR(HistoricalFS!I33/HistoricalFS!H33-1,0) -> -3.554731 | J8: =IFERROR(HistoricalFS!J33/HistoricalFS!I33-1,0) -> 2.372549 | K8: =IFERROR(HistoricalFS!K33/HistoricalFS!J33-1,0) -> 3.0605082 | M8: =IFERROR(AVERAGE(D8:K8),0) -> -0.40667914 | N8: =IFERROR(MEDIAN(D8:K8),0) -> -0.40505014
B9: Dividend Growth | D9: =IFERROR(HistoricalFS!D41/HistoricalFS!C41-1,0) -> 0 | E9: =IFERROR(HistoricalFS!E41/HistoricalFS!D41-1,0) -> 0 | F9: =IFERROR(HistoricalFS!F41/HistoricalFS!E41-1,0) -> 0 | G9: =IFERROR(HistoricalFS!G41/HistoricalFS!F41-1,0) -> 0 | H9: =IFERROR(HistoricalFS!H41/HistoricalFS!G41-1,0) -> 0 | I9: =IFERROR(HistoricalFS!I41/HistoricalFS!H41-1,0) -> 0 | J9: =IFERROR(HistoricalFS!J41/HistoricalFS!I41-1,0) -> 0 | K9: =IFERROR(HistoricalFS!K41/HistoricalFS!J41-1,0) -> 0 | M9: =IFERROR(AVERAGE(D9:K9),0) -> 0 | N9: =IFERROR(MEDIAN(D9:K9),0) -> 0
B11: Gross Margin | C11: =IFERROR(HistoricalFS!C13,0) -> 0.20076259 | D11: =IFERROR(HistoricalFS!D13,0) -> 0.25521194 | E11: =IFERROR(HistoricalFS!E13,0) -> 0.27287797 | F11: =IFERROR(HistoricalFS!F13,0) -> 0.23496251 | G11: =IFERROR(HistoricalFS!G13,0) -> 0.28522976 | H11: =IFERROR(HistoricalFS!H13,0) -> 0.30533847 | I11: =IFERROR(HistoricalFS!I13,0) -> 0.30749511 | J11: =IFERROR(HistoricalFS!J13,0) -> 0.32296706 | K11: =IFERROR(HistoricalFS!K13,0) -> 0.37359402 | M11: =IFERROR(AVERAGE(C11:K11),0) -> 0.28427105 | N11: =IFERROR(MEDIAN(D11:K11),0) -> 0.29528411
B12: EBITDA Margin | C12: =IFERROR(HistoricalFS!C19,0) -> -0.046329828 | D12: =IFERROR(HistoricalFS!D19,0) -> 0.018769289 | E12: =IFERROR(HistoricalFS!E19,0) -> 0.046958185 | F12: =IFERROR(HistoricalFS!F19,0) -> 0.064828547 | G12: =IFERROR(HistoricalFS!G19,0) -> 0.04346916 | H12: =IFERROR(HistoricalFS!H19,0) -> 0.049974727 | I12: =IFERROR(HistoricalFS!I19,0) -> 0.05432197 | J12: =IFERROR(HistoricalFS!J19,0) -> 0.059722107 | K12: =IFERROR(HistoricalFS!K19,0) -> 0.075063234 | M12: =IFERROR(AVERAGE(C12:K12),0) -> 0.040753043 | N12: =IFERROR(MEDIAN(D12:K12),0) -> 0.052148348
B13: EBIT Margin | C13: =IFERROR((HistoricalFS!C18-HistoricalFS!C24)/HistoricalFS!C6,0) -> -0.059213734 | D13: =IFERROR((HistoricalFS!D18-HistoricalFS!D24)/HistoricalFS!D6,0) -> -0.0090157371 | E13: =IFERROR((HistoricalFS!E18-HistoricalFS!E24)/HistoricalFS!E6,0) -> 0.013289732 | F13: =IFERROR((HistoricalFS!F18-HistoricalFS!F24)/HistoricalFS!F6,0) -> 0.035499201 | G13: =IFERROR((HistoricalFS!G18-HistoricalFS!G24)/HistoricalFS!G6,0) -> 0.017922913 | H13: =IFERROR((HistoricalFS!H18-HistoricalFS!H24)/HistoricalFS!H6,0) -> 0.016291458 | I13: =IFERROR((HistoricalFS!I18-HistoricalFS!I24)/HistoricalFS!I6,0) -> 0.019207189 | J13: =IFERROR((HistoricalFS!J18-HistoricalFS!J24)/HistoricalFS!J6,0) -> 0.026211914 | K13: =IFERROR((HistoricalFS!K18-HistoricalFS!K24)/HistoricalFS!K6,0) -> 0.043101668 | M13: =IFERROR(AVERAGE(C13:K13),0) -> 0.011477178 | N13: =IFERROR(MEDIAN(D13:K13),0) -> 0.018565051
B14: EBT Margin | C14: =IFERROR(HistoricalFS!C28,0) -> -0.071679783 | D14: =IFERROR(HistoricalFS!D28,0) -> -0.033030709 | E14: =IFERROR(HistoricalFS!E28,0) -> -0.012871069 | F14: =IFERROR(HistoricalFS!F28,0) -> 0.022270474 | G14: =IFERROR(HistoricalFS!G28,0) -> 0.0053895928 | H14: =IFERROR(HistoricalFS!H28,0) -> 0.001590264 | I14: =IFERROR(HistoricalFS!I28,0) -> 0.0061215573 | J14: =IFERROR(HistoricalFS!J28,0) -> 0.012602801 | K14: =IFERROR(HistoricalFS!K28,0) -> 0.031415786 | M14: =IFERROR(AVERAGE(C14:K14),0) -> -0.004243454 | N14: =IFERROR(MEDIAN(D14:K14),0) -> 0.0057555751
B15: Net Profit Margin | C15: =IFERROR(HistoricalFS!C34,0) -> -0.055540079 | D15: =IFERROR(HistoricalFS!D34,0) -> -0.026570331 | E15: =IFERROR(HistoricalFS!E34,0) -> -0.015083195 | F15: =IFERROR(HistoricalFS!F34,0) -> 0.020435085 | G15: =IFERROR(HistoricalFS!G34,0) -> 0.0037944429 | H15: =IFERROR(HistoricalFS!H34,0) -> -0.0010478634 | I15: =IFERROR(HistoricalFS!I34,0) -> 0.0021564043 | J15: =IFERROR(HistoricalFS!J34,0) -> 0.0058416417 | K15: =IFERROR(HistoricalFS!K34,0) -> 0.018814949 | M15: =IFERROR(AVERAGE(C15:K15),0) -> -0.0052443273 | N15: =IFERROR(MEDIAN(D15:K15),0) -> 0.0029754236
B17: Sales Expense % Sales | C17: =IFERROR(HistoricalFS!C16,0) -> 0.24709242 | D17: =IFERROR(HistoricalFS!D16,0) -> 0.23644265 | E17: =IFERROR(HistoricalFS!E16,0) -> 0.22591979 | F17: =IFERROR(HistoricalFS!F16,0) -> 0.17013397 | G17: =IFERROR(HistoricalFS!G16,0) -> 0.2417606 | H17: =IFERROR(HistoricalFS!H16,0) -> 0.25536374 | I17: =IFERROR(HistoricalFS!I16,0) -> 0.25317314 | J17: =IFERROR(HistoricalFS!J16,0) -> 0.26324495 | K17: =IFERROR(HistoricalFS!K16,0) -> 0.29853078 | M17: =IFERROR(AVERAGE(C17:K17),0) -> 0.243518 | N17: =IFERROR(MEDIAN(D17:K17),0) -> 0.24746687
B18: Depreciation % Sales | C18: =IFERROR(HistoricalFS!C25,0) -> 0.012883906 | D18: =IFERROR(HistoricalFS!D25,0) -> 0.027785026 | E18: =IFERROR(HistoricalFS!E25,0) -> 0.033668453 | F18: =IFERROR(HistoricalFS!F25,0) -> 0.029329346 | G18: =IFERROR(HistoricalFS!G25,0) -> 0.025546246 | H18: =IFERROR(HistoricalFS!H25,0) -> 0.033683269 | I18: =IFERROR(HistoricalFS!I25,0) -> 0.035114781 | J18: =IFERROR(HistoricalFS!J25,0) -> 0.033510193 | K18: =IFERROR(HistoricalFS!K25,0) -> 0.031961566 | M18: =IFERROR(AVERAGE(C18:K18),0) -> 0.029275865 | N18: =IFERROR(MEDIAN(D18:K18),0) -> 0.032735879
B19: Operating Income % Sales | C19: =IFERROR(C13,0) -> -0.059213734 | D19: =IFERROR(D13,0) -> -0.0090157371 | E19: =IFERROR(E13,0) -> 0.013289732 | F19: =IFERROR(F13,0) -> 0.035499201 | G19: =IFERROR(G13,0) -> 0.017922913 | H19: =IFERROR(H13,0) -> 0.016291458 | I19: =IFERROR(I13,0) -> 0.019207189 | J19: =IFERROR(J13,0) -> 0.026211914 | K19: =IFERROR(K13,0) -> 0.043101668 | M19: =IFERROR(AVERAGE(C19:K19),0) -> 0.011477178 | N19: =IFERROR(MEDIAN(D19:K19),0) -> 0.018565051
B21: Return On Capital Employed | C21: =IFERROR((HistoricalFS!C18-HistoricalFS!C24)/SUM(HistoricalFS!C47:C49),0) -> -0.16619429 | D21: =IFERROR((HistoricalFS!D18-HistoricalFS!D24)/SUM(HistoricalFS!D47:D49),0) -> -0.01852023 | E21: =IFERROR((HistoricalFS!E18-HistoricalFS!E24)/SUM(HistoricalFS!E47:E49),0) -> 0.031971363 | F21: =IFERROR((HistoricalFS!F18-HistoricalFS!F24)/SUM(HistoricalFS!F47:F49),0) -> 0.10534058 | G21: =IFERROR((HistoricalFS!G18-HistoricalFS!G24)/SUM(HistoricalFS!G47:G49),0) -> 0.035000931 | H21: =IFERROR((HistoricalFS!H18-HistoricalFS!H24)/SUM(HistoricalFS!H47:H49),0) -> 0.038501829 | I21: =IFERROR((HistoricalFS!I18-HistoricalFS!I24)/SUM(HistoricalFS!I47:I49),0) -> 0.054957611 | J21: =IFERROR((HistoricalFS!J18-HistoricalFS!J24)/SUM(HistoricalFS!J47:J49),0) -> 0.079477625 | K21: =IFERROR((HistoricalFS!K18-HistoricalFS!K24)/SUM(HistoricalFS!K47:K49),0) -> 0.16144017 | M21: =IFERROR(AVERAGE(C21:K21),0) -> 0.035775065 | N21: =IFERROR(MEDIAN(C21:K21),0) -> 0.038501829
B22: Retained Earnings % | C22: =IFERROR(HistoricalFS!C44,0) -> 0 | D22: =IFERROR(HistoricalFS!D44,0) -> 0 | E22: =IFERROR(HistoricalFS!E44,0) -> 0 | F22: =IFERROR(HistoricalFS!F44,0) -> 1 | G22: =IFERROR(HistoricalFS!G44,0) -> 1 | H22: =IFERROR(HistoricalFS!H44,0) -> 0 | I22: =IFERROR(HistoricalFS!I44,0) -> 1 | J22: =IFERROR(HistoricalFS!J44,0) -> 1 | K22: =IFERROR(HistoricalFS!K44,0) -> 1 | M22: =IFERROR(AVERAGE(C22:K22),0) -> 0.55555556 | N22: =IFERROR(MEDIAN(C22:K22),0) -> 1
B23: Return On Equity | C23: =IFERROR(HistoricalFS!C33/SUM(HistoricalFS!C47:C48),0) -> -0.2623571 | D23: =IFERROR(HistoricalFS!D33/SUM(HistoricalFS!D47:D48),0) -> -0.12807946 | E23: =IFERROR(HistoricalFS!E33/SUM(HistoricalFS!E47:E48),0) -> -0.082807889 | F23: =IFERROR(HistoricalFS!F33/SUM(HistoricalFS!F47:F48),0) -> 0.10188533 | G23: =IFERROR(HistoricalFS!G33/SUM(HistoricalFS!G47:G48),0) -> 0.010687365 | H23: =IFERROR(HistoricalFS!H33/SUM(HistoricalFS!H47:H48),0) -> -0.0039114091 | I23: =IFERROR(HistoricalFS!I33/SUM(HistoricalFS!I47:I48),0) -> 0.010909264 | J23: =IFERROR(HistoricalFS!J33/SUM(HistoricalFS!J47:J48),0) -> 0.035687938 | K23: =IFERROR(HistoricalFS!K33/SUM(HistoricalFS!K47:K48),0) -> 0.13113534 | M23: =IFERROR(AVERAGE(C23:K23),0) -> -0.02076118 | N23: =IFERROR(MEDIAN(C23:K23),0) -> 0.010687365
B24: Self Sustained Growth Rate | C24: =IFERROR(C22*C23,0) -> 0 | D24: =IFERROR(D22*D23,0) -> 0 | E24: =IFERROR(E22*E23,0) -> 0 | F24: =IFERROR(F22*F23,0) -> 0.10188533 | G24: =IFERROR(G22*G23,0) -> 0.010687365 | H24: =IFERROR(H22*H23,0) -> 0 | I24: =IFERROR(I22*I23,0) -> 0.010909264 | J24: =IFERROR(J22*J23,0) -> 0.035687938 | K24: =IFERROR(K22*K23,0) -> 0.13113534 | M24: =IFERROR(AVERAGE(C24:K24),0) -> 0.032256137 | N24: =IFERROR(MEDIAN(C24:K24),0) -> 0.010687365
B25: Interest Coverage Ratio | C25: =IFERROR((HistoricalFS!C18-HistoricalFS!C24)/HistoricalFS!C21,0) -> -4.75 | D25: =IFERROR((HistoricalFS!D18-HistoricalFS!D24)/HistoricalFS!D21,0) -> -0.37542151 | E25: =IFERROR((HistoricalFS!E18-HistoricalFS!E24)/HistoricalFS!E21,0) -> 0.50800173 | F25: =IFERROR((HistoricalFS!F18-HistoricalFS!F24)/HistoricalFS!F21,0) -> 2.6834933 | G25: =IFERROR((HistoricalFS!G18-HistoricalFS!G24)/HistoricalFS!G21,0) -> 1.4300211 | H25: =IFERROR((HistoricalFS!H18-HistoricalFS!H24)/HistoricalFS!H21,0) -> 1.1081724 | I25: =IFERROR((HistoricalFS!I18-HistoricalFS!I24)/HistoricalFS!I21,0) -> 1.4678076 | J25: =IFERROR((HistoricalFS!J18-HistoricalFS!J24)/HistoricalFS!J21,0) -> 1.926056 | K25: =IFERROR((HistoricalFS!K18-HistoricalFS!K24)/HistoricalFS!K21,0) -> 3.6883538 | M25: =IFERROR(AVERAGE(C25:K25),0) -> 0.85405384 | N25: =IFERROR(MEDIAN(D25:K25),0) -> 1.4489144
B27: Debtor Turnover Ratio | C27: =IFERROR(HistoricalFS!C6/HistoricalFS!C59,0) -> 8.1771071 | D27: =IFERROR(HistoricalFS!D6/HistoricalFS!D59,0) -> 19.188363 | E27: =IFERROR(HistoricalFS!E6/HistoricalFS!E59,0) -> 17.957228 | F27: =IFERROR(HistoricalFS!F6/HistoricalFS!F59,0) -> 31.848904 | G27: =IFERROR(HistoricalFS!G6/HistoricalFS!G59,0) -> 39.923199 | H27: =IFERROR(HistoricalFS!H6/HistoricalFS!H59,0) -> 31.454779 | I27: =IFERROR(HistoricalFS!I6/HistoricalFS!I59,0) -> 26.430588 | J27: =IFERROR(HistoricalFS!J6/HistoricalFS!J59,0) -> 32.236406 | K27: =IFERROR(HistoricalFS!K6/HistoricalFS!K59,0) -> 34.633872 | M27: =IFERROR(AVERAGE(C27:K27),0) -> 26.872272 | N27: =IFERROR(MEDIAN(D27:K27),0) -> 31.651841
B28: Creditor Turnover Ratio | C28: =IFERROR(HistoricalFS!C6/HistoricalFS!C50,0) -> 3.8677441 | D28: =IFERROR(HistoricalFS!D6/HistoricalFS!D50,0) -> 4.7369789 | E28: =IFERROR(HistoricalFS!E6/HistoricalFS!E50,0) -> 4.5349189 | F28: =IFERROR(HistoricalFS!F6/HistoricalFS!F50,0) -> 5.0918914 | G28: =IFERROR(HistoricalFS!G6/HistoricalFS!G50,0) -> 5.289186 | H28: =IFERROR(HistoricalFS!H6/HistoricalFS!H50,0) -> 6.6504622 | I28: =IFERROR(HistoricalFS!I6/HistoricalFS!I50,0) -> 5.4628928 | J28: =IFERROR(HistoricalFS!J6/HistoricalFS!J50,0) -> 5.8555308 | K28: =IFERROR(HistoricalFS!K6/HistoricalFS!K50,0) -> 5.1779302 | M28: =IFERROR(AVERAGE(C28:K28),0) -> 5.1852817 | N28: =IFERROR(MEDIAN(D28:K28),0) -> 5.2335581
B29: Inventory Turnover Ratio | C29: =IFERROR(HistoricalFS!C6/HistoricalFS!C60,0) -> 4.879035 | D29: =IFERROR(HistoricalFS!D6/HistoricalFS!D60,0) -> 4.543704 | E29: =IFERROR(HistoricalFS!E6/HistoricalFS!E60,0) -> 3.9689451 | F29: =IFERROR(HistoricalFS!F6/HistoricalFS!F60,0) -> 4.90052 | G29: =IFERROR(HistoricalFS!G6/HistoricalFS!G60,0) -> 4.3100203 | H29: =IFERROR(HistoricalFS!H6/HistoricalFS!H60,0) -> 5.1174961 | I29: =IFERROR(HistoricalFS!I6/HistoricalFS!I60,0) -> 5.3568474 | J29: =IFERROR(HistoricalFS!J6/HistoricalFS!J60,0) -> 5.6081804 | K29: =IFERROR(HistoricalFS!K6/HistoricalFS!K60,0) -> 6.1031507 | M29: =IFERROR(AVERAGE(C29:K29),0) -> 4.9764332 | N29: =IFERROR(MEDIAN(D29:K29),0) -> 5.009008
B30: Fixed Asset Turnover Ratio | C30: =IFERROR(HistoricalFS!C6/HistoricalFS!C53,0) -> 16.833529 | D30: =IFERROR(HistoricalFS!D6/HistoricalFS!D53,0) -> 7.9623872 | E30: =IFERROR(HistoricalFS!E6/HistoricalFS!E53,0) -> 7.7854469 | F30: =IFERROR(HistoricalFS!F6/HistoricalFS!F53,0) -> 10.560723 | G30: =IFERROR(HistoricalFS!G6/HistoricalFS!G53,0) -> 7.8094982 | H30: =IFERROR(HistoricalFS!H6/HistoricalFS!H53,0) -> 7.3606937 | I30: =IFERROR(HistoricalFS!I6/HistoricalFS!I53,0) -> 9.5570372 | J30: =IFERROR(HistoricalFS!J6/HistoricalFS!J53,0) -> 9.5227953 | K30: =IFERROR(HistoricalFS!K6/HistoricalFS!K53,0) -> 9.9433008 | M30: =IFERROR(AVERAGE(C30:K30),0) -> 9.7039346 | N30: =IFERROR(MEDIAN(D30:K30),0) -> 8.7425912
B31: Capital Turnover Ratio | C31: =IFERROR(HistoricalFS!C6/SUM(HistoricalFS!C47:C48),0) -> 4.7237437 | D31: =IFERROR(HistoricalFS!D6/SUM(HistoricalFS!D47:D48),0) -> 4.8203938 | E31: =IFERROR(HistoricalFS!E6/SUM(HistoricalFS!E47:E48),0) -> 5.4900761 | F31: =IFERROR(HistoricalFS!F6/SUM(HistoricalFS!F47:F48),0) -> 4.9858039 | G31: =IFERROR(HistoricalFS!G6/SUM(HistoricalFS!G47:G48),0) -> 2.8165833 | H31: =IFERROR(HistoricalFS!H6/SUM(HistoricalFS!H47:H48),0) -> 3.732747 | I31: =IFERROR(HistoricalFS!I6/SUM(HistoricalFS!I47:I48),0) -> 5.0590067 | J31: =IFERROR(HistoricalFS!J6/SUM(HistoricalFS!J47:J48),0) -> 6.1092309 | K31: =IFERROR(HistoricalFS!K6/SUM(HistoricalFS!K47:K48),0) -> 6.9697423 | M31: =IFERROR(AVERAGE(C31:K31),0) -> 4.9674809 | N31: =IFERROR(MEDIAN(D31:K31),0) -> 5.0224053
B33: Debtor Days | C33: =IFERROR(365/C27,0) -> 44.636813 | D33: =IFERROR(365/D27,0) -> 19.021945 | E33: =IFERROR(365/E27,0) -> 20.326077 | F33: =IFERROR(365/F27,0) -> 11.460363 | G33: =IFERROR(365/G27,0) -> 9.1425539 | H33: =IFERROR(365/H27,0) -> 11.60396 | I33: =IFERROR(365/I27,0) -> 13.809757 | J33: =IFERROR(365/J27,0) -> 11.322602 | K33: =IFERROR(365/K27,0) -> 10.538816 | M33: =IFERROR(AVERAGE(C33:K33),0) -> 16.873654 | N33: =IFERROR(MEDIAN(D33:K33),0) -> 11.532162
B34: Payable Days | C34: =IFERROR(365/C28,0) -> 94.370256 | D34: =IFERROR(365/D28,0) -> 77.05333 | E34: =IFERROR(365/E28,0) -> 80.486555 | F34: =IFERROR(365/F28,0) -> 71.682597 | G34: =IFERROR(365/G28,0) -> 69.008728 | H34: =IFERROR(365/H28,0) -> 54.883403 | I34: =IFERROR(365/I28,0) -> 66.814418 | J34: =IFERROR(365/J28,0) -> 62.334229 | K34: =IFERROR(365/K28,0) -> 70.491487 | M34: =IFERROR(AVERAGE(C34:K34),0) -> 71.902778 | N34: =IFERROR(MEDIAN(D34:K34),0) -> 69.750107
B35: Inventory Days | C35: =IFERROR(365/C29,0) -> 74.809875 | D35: =IFERROR(365/D29,0) -> 80.330937 | E35: =IFERROR(365/E29,0) -> 91.963984 | F35: =IFERROR(365/F29,0) -> 74.481892 | G35: =IFERROR(365/G29,0) -> 84.686376 | H35: =IFERROR(365/H29,0) -> 71.323943 | I35: =IFERROR(365/I29,0) -> 68.137091 | J35: =IFERROR(365/J29,0) -> 65.083499 | K35: =IFERROR(365/K29,0) -> 59.805175 | M35: =IFERROR(AVERAGE(C35:K35),0) -> 74.513641 | N35: =IFERROR(MEDIAN(D35:K35),0) -> 72.902918
B36: Cash Conversion Cycle | C36: =(C33+C35)-C34 -> 25.076433 | D36: =(D33+D35)-D34 -> 22.299553 | E36: =(E33+E35)-E34 -> 31.803505 | F36: =(F33+F35)-F34 -> 14.259658 | G36: =(G33+G35)-G34 -> 24.820201 | H36: =(H33+H35)-H34 -> 28.0445 | I36: =(I33+I35)-I34 -> 15.13243 | J36: =(J33+J35)-J34 -> 14.071872 | K36: =(K33+K35)-K34 -> -0.14749535 | M36: =IFERROR(AVERAGE(C36:K36),0) -> 19.484518 | N36: =IFERROR(MEDIAN(D36:K36),0) -> 18.715991
B38: CFO/Sales | C38: =IFERROR(HistoricalFS!C78/HistoricalFS!C6,0) -> -0.22807995 | D38: =IFERROR(HistoricalFS!D78/HistoricalFS!D6,0) -> -0.20424873 | E38: =IFERROR(HistoricalFS!E78/HistoricalFS!E6,0) -> -0.040734811 | F38: =IFERROR(HistoricalFS!F78/HistoricalFS!F6,0) -> 0.03892007 | G38: =IFERROR(HistoricalFS!G78/HistoricalFS!G6,0) -> -0.21727955 | H38: =IFERROR(HistoricalFS!H78/HistoricalFS!H6,0) -> -0.091372137 | I38: =IFERROR(HistoricalFS!I78/HistoricalFS!I6,0) -> -0.039150405 | J38: =IFERROR(HistoricalFS!J78/HistoricalFS!J6,0) -> 0.061259249 | K38: =IFERROR(HistoricalFS!K78/HistoricalFS!K6,0) -> 0.062859509 | M38: =IFERROR(AVERAGE(C38:K38),0) -> -0.073091862 | N38: =IFERROR(MEDIAN(D38:K38),0) -> -0.039942608
B39: CFO/Total Assets | C39: =IFERROR(HistoricalFS!C78/HistoricalFS!C64,0) -> -0.37095769 | D39: =IFERROR(HistoricalFS!D78/HistoricalFS!D64,0) -> -0.29265777 | E39: =IFERROR(HistoricalFS!E78/HistoricalFS!E64,0) -> -0.064029596 | F39: =IFERROR(HistoricalFS!F78/HistoricalFS!F64,0) -> 0.072968032 | G39: =IFERROR(HistoricalFS!G78/HistoricalFS!G64,0) -> -0.30989705 | H39: =IFERROR(HistoricalFS!H78/HistoricalFS!H64,0) -> -0.15932365 | I39: =IFERROR(HistoricalFS!I78/HistoricalFS!I64,0) -> -0.07351579 | J39: =IFERROR(HistoricalFS!J78/HistoricalFS!J64,0) -> 0.12237626 | K39: =IFERROR(HistoricalFS!K78/HistoricalFS!K64,0) -> 0.13661854 | M39: =IFERROR(AVERAGE(C39:K39),0) -> -0.10426875 | N39: =IFERROR(MEDIAN(D39:K39),0) -> -0.068772693
B40: CFO/Total Debt | C40: =IFERROR(HistoricalFS!C78/HistoricalFS!C49,0) -> -1.577363 | D40: =IFERROR(HistoricalFS!D78/HistoricalFS!D49,0) -> -0.73114955 | E40: =IFERROR(HistoricalFS!E78/HistoricalFS!E49,0) -> -0.17443128 | F40: =IFERROR(HistoricalFS!F78/HistoricalFS!F49,0) -> 0.28528529 | G40: =IFERROR(HistoricalFS!G78/HistoricalFS!G49,0) -> -1.383686 | H40: =IFERROR(HistoricalFS!H78/HistoricalFS!H49,0) -> -0.58860363 | I40: =IFERROR(HistoricalFS!I78/HistoricalFS!I49,0) -> -0.25786754 | J40: =IFERROR(HistoricalFS!J78/HistoricalFS!J49,0) -> 0.36877456 | K40: =IFERROR(HistoricalFS!K78/HistoricalFS!K49,0) -> 0.50896341 | M40: =IFERROR(AVERAGE(C40:K40),0) -> -0.39445309 | N40: =IFERROR(MEDIAN(D40:K40),0) -> -0.21614941

Sheet Forecasting
B2: ="FSN E-Commerce "&"-"&" Sales Growth" -> FSN E-Commerce - Sales Growth | G2: ="FSN E-Commerce "&"-"&" EBITDA Growth" -> FSN E-Commerce - EBITDA Growth | L2: ="FSN E-Commerce "&"-"&" Net Profit Growth" -> FSN E-Commerce - Net Profit Growth
B3: Year Weight | C3: Year | D3: Sales | E3: Sales Growth | G3: Year Weight | H3: Year | I3: EBITDA | J3: EBITDA Growth | L3: Year Weight | M3: Year | N3: Net Profit | O3: Net Profit Growth
B4: 1 | C4: 2018 | D4: 574.36 | G4: 1 | H4: 2018 | I4: =FORECAST(G4,$D$4:$D$12,$B$4:$B$12) -> -330.89889 | L4: 1 | M4: 2018 | N4: g
B5: =B4+1 -> 2 | C5: =C4+1 -> 2019 | D5: 1111.39 | E5: =D5/D4-1 -> 0.93500592 | G5: =G4+1 -> 2 | H5: =H4+1 -> 2019 | I5: =FORECAST(G5,$D$4:$D$12,$B$4:$B$12) -> 839.87361 | J5: =I5/I4-1 -> -3.5381578 | L5: =L4+1 -> 2 | M5: =M4+1 -> 2019 | N5: -36.71 | O5: =N5/N4-1 -> #VALUE!
B6: =B5+1 -> 3 | C6: =C5+1 -> 2020 | D6: 1767.53 | E6: =D6/D5-1 -> 0.59037782 | G6: =G5+1 -> 3 | H6: =H5+1 -> 2020 | I6: =FORECAST(G6,$D$4:$D$12,$B$4:$B$12) -> 2010.6461 | J6: =I6/I5-1 -> 1.3939865 | L6: =L5+1 -> 3 | M6: =M5+1 -> 2020 | N6: -22.75 | O6: =N6/N5-1 -> -0.38027785
B7: =B6+1 -> 4 | C7: =C6+1 -> 2021 | D7: 2440.9 | E7: =D7/D6-1 -> 0.38096666 | G7: =G6+1 -> 4 | H7: =H6+1 -> 2021 | I7: =FORECAST(G7,$D$4:$D$12,$B$4:$B$12) -> 3181.4186 | J7: =I7/I6-1 -> 0.58228671 | L7: =L6+1 -> 4 | M7: =M6+1 -> 2021 | N7: 54.36 | O7: =N7/N6-1 -> -3.3894505
B8: =B7+1 -> 5 | C8: =C7+1 -> 2022 | D8: 3773.94 | E8: =D8/D7-1 -> 0.54612643 | G8: =G7+1 -> 5 | H8: =H7+1 -> 2022 | I8: =FORECAST(G8,$D$4:$D$12,$B$4:$B$12) -> 4352.1911 | J8: =I8/I7-1 -> 0.36800329 | L8: =L7+1 -> 5 | M8: =M7+1 -> 2022 | N8: 20.34 | O8: =N8/N7-1 -> -0.62582781
B9: =B8+1 -> 6 | C9: =C8+1 -> 2023 | D9: 5143.8 | E9: =D9/D8-1 -> 0.36297874 | G9: =G8+1 -> 6 | H9: =H8+1 -> 2023 | I9: =FORECAST(G9,$D$4:$D$12,$B$4:$B$12) -> 5522.9636 | J9: =I9/I8-1 -> 0.2690076 | L9: =L8+1 -> 6 | M9: =M8+1 -> 2023 | N9: 8.18 | O9: =N9/N8-1 -> -0.59783677
B10: =B9+1 -> 7 | C10: =C9+1 -> 2024 | D10: 6385.63 | E10: =D10/D9-1 -> 0.24142268 | G10: =G9+1 -> 7 | H10: =H9+1 -> 2024 | I10: =FORECAST(G10,$D$4:$D$12,$B$4:$B$12) -> 6693.7361 | J10: =I10/I9-1 -> 0.21198266 | L10: =L9+1 -> 7 | M10: =M9+1 -> 2024 | N10: 39.09 | O10: =N10/N9-1 -> 3.7787286
B11: =B10+1 -> 8 | C11: =C10+1 -> 2025 | D11: 7949.82 | E11: =D11/D10-1 -> 0.24495469 | G11: =G10+1 -> 8 | H11: =H10+1 -> 2025 | I11: =FORECAST(G11,$D$4:$D$12,$B$4:$B$12) -> 7864.5086 | J11: =I11/I10-1 -> 0.17490569 | L11: =L10+1 -> 8 | M11: =M10+1 -> 2025 | N11: 100.19 | O11: =N11/N10-1 -> 1.5630596
B12: =B11+1 -> 9 | C12: =C11+1 -> 2026 | D12: 10022.35 | E12: =D12/D11-1 -> 0.2607015 | G12: =G11+1 -> 9 | H12: =H11+1 -> 2026 | I12: =FORECAST(G12,$D$4:$D$12,$B$4:$B$12) -> 9035.2811 | J12: =I12/I11-1 -> 0.14886785 | L12: =L11+1 -> 9 | M12: =M11+1 -> 2026 | N12: 314.86 | O12: =N12/N11-1 -> 2.142629
B13: =B12+1 -> 10 | C13: =C12+1 -> 2027 | D13: =FORECAST(B13,$D$4:$D$12,$B$4:$B$12) -> 10206.054 | E13: =D13/D12-1 -> 0.018329395 | G13: =G12+1 -> 10 | H13: =H12+1 -> 2027 | I13: =FORECAST(G13,$D$4:$D$12,$B$4:$B$12) -> 10206.054 | J13: =I13/I12-1 -> 0.12957787 | L13: =L12+1 -> 10 | M13: =M12+1 -> 2027 | N13: =FORECAST(L13,$N$4:$N$12,$L$4:$L$12) -> 221.35857 | O13: =N13/N12-1 -> -0.29696192
B14: =B13+1 -> 11 | C14: =C13+1 -> 2028 | D14: =FORECAST(B14,$D$4:$D$12,$B$4:$B$12) -> 11376.826 | E14: =D14/D13-1 -> 0.11471354 | G14: =G13+1 -> 11 | H14: =H13+1 -> 2028 | I14: =FORECAST(G14,$D$4:$D$12,$B$4:$B$12) -> 11376.826 | J14: =I14/I13-1 -> 0.11471354 | L14: =L13+1 -> 11 | M14: =M13+1 -> 2028 | N14: =FORECAST(L14,$N$4:$N$12,$L$4:$L$12) -> 257.28381 | O14: =N14/N13-1 -> 0.16229432
B15: =B14+1 -> 12 | C15: =C14+1 -> 2029 | D15: =FORECAST(B15,$D$4:$D$12,$B$4:$B$12) -> 12547.599 | E15: =D15/D14-1 -> 0.10290853 | G15: =G14+1 -> 12 | H15: =H14+1 -> 2029 | I15: =FORECAST(G15,$D$4:$D$12,$B$4:$B$12) -> 12547.599 | J15: =I15/I14-1 -> 0.10290853 | L15: =L14+1 -> 12 | M15: =M14+1 -> 2029 | N15: =FORECAST(L15,$N$4:$N$12,$L$4:$L$12) -> 293.20905 | O15: =N15/N14-1 -> 0.13963272
B16: =B15+1 -> 13 | C16: =C15+1 -> 2030 | D16: =FORECAST(B16,$D$4:$D$12,$B$4:$B$12) -> 13718.371 | E16: =D16/D15-1 -> 0.093306499 | G16: =G15+1 -> 13 | H16: =H15+1 -> 2030 | I16: =FORECAST(G16,$D$4:$D$12,$B$4:$B$12) -> 13718.371 | J16: =I16/I15-1 -> 0.093306499 | L16: =L15+1 -> 13 | M16: =M15+1 -> 2030 | N16: =FORECAST(L16,$N$4:$N$12,$L$4:$L$12) -> 329.13429 | O16: =N16/N15-1 -> 0.12252432
B18: Arithmetic Mean | D18: =AVERAGE(E5:E12) -> 0.4453168
B19: Geometric Mean | D19: =_xlfn.RRI(B12,D4,D12) -> 0.37396653
B20: Standard Deviation | D20: =_xlfn.STDEV.S(E5:E12) -> 0.23836401

Sheet Common Size Statements

Sheet Peer Analysis

Sheet WACC
B2: Weighted Average Cost of Capital
B4: All figures in INR unless stated otherwise
B6: Peer comps
H7: Debt / | I7: Debt / | J7: Levered | K7: Unlevered
B8: Name of the Comp | D8: Country | E8: Total Debt | F8: Total Equity | G8: Tax Rate 1 | H8: Equity | I8: Capital | J8: Beta 2 | K8: Beta 3

Sheet Data>

Sheet Data Sheet
A1: COMPANY NAME | B1: FSN E-COMMERCE VENTURES LTD | E1: =IF(B2<>B3, "A NEW VERSION OF THE WORKSHEET IS AVAILABLE", "")
A2: LATEST VERSION | B2: 2.1 | E2: PLEASE DO NOT MAKE ANY CHANGES TO THIS SHEET
A3: CURRENT VERSION | B3: 2.1
A5: META
A6: Number of shares | B6: =IF(B9>0, B9/B8, 0) -> 286.3824
A7: Face Value | B7: 1
A8: Current Price | B8: 302.3
A9: Market Capitalization | B9: 86573.4
A15: PROFIT & LOSS
A16: Report Date | C16: 43190 | D16: 43555 | E16: 43921 | F16: 44286 | G16: 44651 | H16: 45016 | I16: 45382 | J16: 45747 | K16: 46112
A17: Sales | C17: 574.36 | D17: 1111.39 | E17: 1767.53 | F17: 2440.9 | G17: 3773.94 | H17: 5143.8 | I17: 6385.63 | J17: 7949.82 | K17: 10022.35
A18: Raw Material Cost | C18: 436.16 | D18: 785.48 | E18: 1196.09 | F18: 1533.85 | G18: 2492.14 | H18: 3007.42 | I18: 3846.79 | J18: 4691.18 | K18: 5733.19
A19: Change in Inventory | C19: 59.93 | D19: 125.21 | E19: 181.88 | F19: 41.27 | G19: 362.13 | H19: 141.74 | I19: 200.4 | J19: 218.52 | K19: 226.66
A20: Power and Fuel | C20: 0.6 | D20: 2.09 | E20: 4.62 | F20: 4.4 | G20: 6.64 | H20: 14.99 | I20: 20.68 | J20: 25.83
A21: Other Mfr. Exp | C21: 27.29 | D21: 48.09 | E21: 70.75 | F21: 137.03 | G21: 233.28 | H21: 199.27 | I21: 188.75 | J21: 216.21
A22: Employee Cost | C22: 54.93 | D22: 117.3 | E22: 195.63 | F22: 233.37 | G22: 327.57 | H22: 493.26 | I22: 566.26 | J22: 667.59 | K22: 771.53
A23: Selling and admin | C23: 139.22 | D23: 253.12 | E23: 387.59 | F23: 389.05 | G23: 886.55 | H23: 1300.56 | I23: 1591.29 | J23: 2071.9
A24: Other Expenses | C24: 2.7 | D24: 9.66 | E24: 11.73 | F24: 26.23 | G24: 25.84 | H24: 12.98 | I24: 25.38 | J24: 20.85 | K24: 2991.98
A25: Other Income | C25: 3.72 | D25: 4.99 | E25: 10.32 | F25: 11.76 | G25: 26.97 | H25: 30.21 | I25: 29.94 | J25: 27.26 | K25: 15.37
A26: Depreciation | C26: 7.4 | D26: 30.88 | E26: 59.51 | F26: 71.59 | G26: 96.41 | H26: 173.26 | I26: 224.23 | J26: 266.4 | K26: 320.33
A27: Interest | C27: 7.16 | D27: 26.69 | E27: 46.24 | F27: 32.29 | G27: 47.3 | H27: 75.62 | I27: 83.56 | J27: 108.19 | K27: 117.12
A28: Profit before tax | C28: -37.45 | D28: -31.72 | E28: -12.43 | F28: 66.12 | G28: 47.31 | H28: 38.39 | I28: 69.03 | J28: 127.45 | K28: 330.23
A29: Tax | C29: -9.27 | D29: -7.18 | E29: 3.91 | F29: 4.48 | G29: 6.02 | H29: 13.57 | I29: 25.32 | J29: 53.75 | K29: 126.29
A30: Net profit | C30: -28.18 | D30: -24.52 | E30: -16.61 | F30: 61.55 | G30: 41.08 | H30: 19.26 | I30: 32.27 | J30: 66.08 | K30: 199.44
A31: Dividend Amount
A40: Quarters
A41: Report Date | B41: 45291 | C41: 45382 | D41: 45473 | E41: 45565 | F41: 45657 | G41: 45747 | H41: 45838 | I41: 45930 | J41: 46022 | K41: 46112
A42: Sales | B42: 1788.8 | C42: 1667.98 | D42: 1746.11 | E42: 1874.74 | F42: 2267.21 | G42: 2061.76 | H42: 2154.94 | I42: 2345.98 | J42: 2873.26 | K42: 2648.17
A43: Expenses | B43: 1690.02 | C43: 1574.7 | D43: 1649.99 | E43: 1771.08 | F43: 2126.43 | G43: 1928.41 | H43: 2014.26 | I43: 2187.03 | J43: 2643.5 | K43: 2425.25
A44: Other Income | B44: 7.58 | C44: 7.06 | D44: 7.33 | E44: 5.45 | F44: 5.53 | G44: 8.95 | H44: 9.33 | I44: 6.99 | J44: -10.1 | K44: 9.15
A45: Depreciation | B45: 58.03 | C45: 59.65 | D45: 60.06 | E45: 63.62 | F45: 69.82 | G45: 72.9 | H45: 76.14 | I45: 79.09 | J45: 80.88 | K45: 84.22
A46: Interest | B46: 21.84 | C46: 21.13 | D46: 21.31 | E46: 24.23 | F46: 31.93 | G46: 29.85 | H46: 30.16 | I46: 31.47 | J46: 29.16 | K46: 26.33
A47: Profit before tax | B47: 26.49 | C47: 19.56 | D47: 22.08 | E47: 21.26 | F47: 44.56 | G47: 39.55 | H47: 43.71 | I47: 55.38 | J47: 109.62 | K47: 121.52
A48: Tax | B48: 8.26 | C48: 9.83 | D48: 7.84 | E48: 7.82 | F48: 17.59 | G48: 20.5 | H48: 19.24 | I48: 22.4 | J48: 41.88 | K48: 42.77
A49: Net profit | B49: 16.19 | C49: 6.93 | D49: 9.64 | E49: 10.04 | F49: 26.12 | G49: 20.28 | H49: 23.32 | I49: 34.43 | J49: 63.31 | K49: 78.38
A50: Operating Profit | B50: 98.78 | C50: 93.28 | D50: 96.12 | E50: 103.66 | F50: 140.78 | G50: 133.35 | H50: 140.68 | I50: 158.95 | J50: 229.76 | K50: 222.92
A55: BALANCE SHEET
A56: Report Date | C56: 43190 | D56: 43555 | E56: 43921 | F56: 44286 | G56: 44651 | H56: 45016 | I56: 45382 | J56: 45747 | K56: 46112
A57: Equity Share Capital | C57: 13.56 | D57: 14.24 | E57: 14.55 | F57: 15.06 | G57: 47.41 | H57: 285.25 | I57: 285.6 | J57: 285.93 | K57: 286.33
A58: Reserves | C58: 108.03 | D58: 216.32 | E58: 307.4 | F58: 474.51 | G58: 1292.49 | H58: 1092.77 | I58: 976.63 | J58: 1015.35 | K58: 1151.65
...

Sheet Cash Flow Data
C2: 43160 | D2: 43525 | E2: 43891 | F2: 44256 | G2: 44621 | H2: 44986 | I2: 45352 | J2: 45717 | K2: 46082
B3: Cash from Operating Activity - | C3: -79 | D3: -100 | E3: 6 | F3: 133 | G3: -354 | H3: -140 | I3: 0 | J3: 467 | K3: 644
B4: Profit from operations | C4: -26 | D4: 29 | E4: 89 | F4: 186 | G4: 183 | H4: 284 | I4: 383 | J4: 505 | K4: 795
B5: Receivables | C5: -48 | D5: 7 | E5: -40 | F5: 15 | G5: -14 | H5: -72 | I5: -89 | J5: -4 | K5: -47
B6: Inventory | C6: -60 | D6: -126 | E6: -201 | F6: -47 | G6: -372 | H6: -130 | I6: -187 | J6: -217 | K6: -225
B7: Payables | C7: 55 | D7: 57 | E7: 132 | F7: 2 | G7: 41 | H7: -99 | I7: 122 | J7: 246 | K7: 98
B8: Loans Advances | C8: -23 | D8: -6 | E8: -6 | F8: 0 | G8: 0 | H8: 0 | I8: 0 | J8: 0 | K8: 0
B9: Other WC items | C9: 24 | D9: -60 | E9: 37 | F9: -9 | G9: -121 | H9: -29 | I9: -97 | J9: -4 | K9: 159
B10: Working capital changes | C10: -53 | D10: -128 | E10: -79 | F10: -39 | G10: -465 | H10: -329 | I10: -251 | J10: 21 | K10: -15
B11: Direct taxes | C11: 0 | D11: 0 | E11: -4 | F11: -13 | G11: -72 | H11: -95 | I11: -131 | J11: -60 | K11: -135
B12: Cash from Investing Activity - | C12: 31 | D12: -162 | E12: 15 | F12: -130 | G12: -603 | H12: 140 | I12: -10 | J12: -205 | K12: -159
B13: Fixed assets purchased | C13: -27 | D13: -35 | E13: -46 | F13: -42 | G13: -94 | H13: -208 | I13: -111 | J13: -127 | K13: -154
B14: Fixed assets sold | C14: 0 | D14: 0 | E14: 0 | F14: 0 | G14: 0 | H14: 0 | I14: 0 | J14: 0 | K14: 2
... B32: CFO/OP | C32: 2.98 | D32: -4.78 | E32: 0.13 | F32: 0.92 | G32: -1.72 | H32: -0.18 | I32: 0.38 | J32: 1.11 | K32: 1.04
